Workbook

Sheet 人员表
A1: 序号 | B1: 部门 | C1: 姓名 | D1: 身份证 | E1: 社保缴纳月份 | F1: 入职时间 | G1: 学历 | H1: 学校 | I1: 专业 | J1: 备注
A3: 1 | B3: 昱奇工程 | C3: 张鸿志 | D3: 150102196612072557 | E3: 45108 | F3: 45027 | G3: 大专 | H3: 长春电力专科学校 | I3: 高电压技术 | K3: {=VLOOKUP(项目人员总表!B5:B24,C3:C43,1,0)} -> 张鸿志 | L3: {=VLOOKUP(C3:C43,项目人员总表!B5:B24,1,0)} -> 张鸿志
A4: 2 | B4: 昱奇工程 | C4: 顾聪飞 | D4: 310230198110155352 | E4: 45108 | F4: 45108 | G4: 大专 | H4: 0 | I4: 0 | J4: 园林 | K4: 孙满涛 | L4: #N/A
A5: 3 | B5: 昱奇工程 | C5: 孙满涛 | D5: 230521198305111317 | E5: 45139 | F5: 45131 | G5: 本科 | H5: 哈尔滨商业大学 | I5: 土木工程 | K5: 邹智伟 | L5: 孙满涛
A6: 4 | B6: 筹建部 | C6: 邹智伟 | D6: 310226198708070316 | E6: 45170 | F6: 45174 | G6: 大专 | H6: 天津大学 | I6: 建筑工程技术 | K6: 王雷 | L6: 邹智伟
A7: 5 | B7: 营销部 | C7: 刘远志 | D7: 510525196904210310 | E7: 45170 | F7: 45170 | G7: 初中 | H7: 古蔺太平中心小学 | I7: 0 | K7: 张晓青 | L7: #N/A
A8: 6 | B8: 昱奇工程 | C8: 王雷 | D8: 231004198102200771 | E8: 45200 | F8: 45176 | G8: 本科 | H8: 东北农业大学 | I8: 经济管理 | K8: 鲍廉梵 | L8: 王雷
A9: 7 | B9: 筹建部 | C9: 张晓青 | D9: 31022619860524351X | E9: 45231 | F9: 45233 | G9: 本科 | H9: 华东政法大学 | I9: 法学 | K9: 李文强 | L9: 张晓青
A10: 8 | B10: 企管部 | C10: 鲍廉梵 | D10: 310102198409304411 | E10: 45383 | F10: 45376 | G10: 大专 | H10: 华东理工大学 | I10: 电子商务 | K10: 薛飞阳 | L10: 鲍廉梵
A11: 9 | B11: 生产部 | C11: 李文强 | D11: 420625197903052013 | E11: 45383 | F11: 45383 | G11: 大专 | H11: 谷城县技工学校 | I11: 电气自动化 | K11: 麻凤娟 | L11: 李文强
A12: 10 | B12: 生产部 | C12: 李陈龙 | D12: 342422199710172394 | E12: 45383 | F12: 45383 | G12: 高中 | H12: 寿县二中 | I12: 0 | K12: 黄丽娇 | L12: #N/A
A13: 11 | B13: 生产部 | C13: 赵红雷 | D13: 370882198212026113 | E13: 45383 | F13: 45383 | G13: 中专 | H13: 济宁省兖州区第一职业中专 | I13: 机电 | K13: 韦继勇 | L13: #N/A
A14: 12 | B14: 生产部 | C14: 薛飞阳 | D14: 610481199501066257 | E14: 45383 | F14: 45383 | G14: 大专 | H14: 广东科技学院 | I14: 应用电子技术 | K14: 徐熙堂 | L14: 薛飞阳
A15: 13 | B15: 项目组 | C15: 麻凤娟 | D15: 452623198608232723 | E15: 45413 | F15: 45363 | G15: 本科 | H15: 桂林理工大学 | I15: 土木工程 | K15: 陶书华 | L15: 麻凤娟
A16: 14 | B16: 项目组 | C16: 黄丽娇 | D16: 452631199001160529 | E16: 45413 | F16: 45418 | G16: 大专 | H16: 广西水利电力职业技术学院 | I16: 电气自动化技术 | K16: 韦诚 | L16: 黄丽娇
A17: 15 | B17: 项目组 | C17: 韦彪 | D17: 452601199502212712 | E17: 45505 | F17: 45505 | G17: 高中 | H17: 百色市一中 | I17: 0 | K17: 廖梅佟 | L17: #N/A
A18: 16 | B18: 项目组 | C18: 徐熙堂 | D18: 452630199609254375 | E18: 45505 | F18: 45505 | G18: 大专 | H18: 广西交通职业技术学院 | I18: 汽车电子技术 | K18: 许方耀 | L18: 徐熙堂
A19: 17 | B19: 项目组 | C19: 覃辽南 | D19: 452731197309156610 | E19: 45505 | F19: 45512 | G19: 中专 | H19: 中央广播电视中等专业学校 | I19: 建筑工程施工 | K19: 龙玉涛 | L19: #N/A
A20: 18 | B20: 行政部 | C20: 徐冠宇 | D20: 342423199607086670 | E20: 45536 | F20: 45536 | G20: 大专 | H20: 安徽财贸职业学院 | I20: 会计 | K20: 伍世昀 | L20: #N/A
A21: 19 | B21: 项目组 | C21: 陶书华 | D21: 452427197910033178 | E21: 45536 | F21: 45536 | G21: 本科 | H21: 重庆大学 | I21: 土木工程 | K21: 许挣伟 | L21: 陶书华
A22: 20 | B22: 项目组 | C22: 韦诚 | D22: 45263120000914051X | E22: 45597 | F22: 45575 | G22: 本科 | H22: 南宁理工学院 | I22: 土木工程 | K22: 黄美为 | L22: 韦诚
A23: 21 | B23: 项目组 | C23: 许蓝丹 | D23: 452624198705130741 | E23: 45597 | F23: 45597 | G23: 本科 | H23: 桂林电子科技大学 | I23: 行政管理 | L23: #N/A
A24: 22 | B24: 项目组 | C24: 梁超诗 | D24: 450481199004081253 | E24: 45627 | F24: 45627 | G24: 高中 | H24: 广西岑溪市第三中学 | I24: / | L24: #N/A
A25: 23 | B25: 项目组 | C25: 廖梅佟 | D25: 451002200307082420 | E25: 45689 | F25: 45644 | G25: 大专 | H25: 广西水利电力职业技术学院 | I25: 供用电技术 | L25: 廖梅佟
A26: 24 | B26: 项目组 | C26: 吴鸿艳 | D26: 452629199908100346 | E26: 45748 | F26: 45748 | G26: 大专 | H26: 广西交通职业技术学院 | I26: 会计学 | L26: #N/A
A27: 25 | B27: 项目组 | C27: 杨秀兰 | D27: 452630199503140628 | E27: 45748 | F27: 45748 | G27: 本科 | H27: 南宁学院 | I27: 会计学 | L27: #N/A
A28: 26 | B28: 项目组 | C28: 许少宏 | D28: 45260119870526151X | E28: 45778 | F28: 45778 | G28: 中专 | H28: 百色市机电工程学院 | I28: 电子技术应用 | L28: #N/A
A29: 27 | B29: 项目组 | C29: 王律颖 | D29: 452629199006180041 | E29: 45809 | F29: 45799 | G29: 本科 | H29: 桂林理工大学 | I29: 会计学 | L29: #N/A
A30: 28 | B30: 项目组 | C30: 许方耀 | D30: 452624200009020717 | E30: 45809 | F30: 45809 | G30: 大专 | H30: 广西工程职业学院 | I30: 建筑工程技术 | L30: 许方耀
A31: 29 | B31: 项目组 | C31: 龙玉涛 | D31: 452624200009020717 | E31: 45809 | F31: 45811 | G31: 大专 | H31: 广西安全工程职业技术学院 | I31: 机电一体化技术专业 | L31: 龙玉涛
A32: 30 | B32: 项目组 | C32: 伍世昀 | D32: 452201199402211219 | E32: 45840 | F32: 45831 | G32: 大专 | H32: 广西电力职业技术学校 | I32: 火电厂集控运行 | L32: 伍世昀
A33: 31 | B33: 项目组 | C33: 许挣伟 | D33: 452629199708060036 | E33: 45841 | F33: 45839 | G33: 本科 | H33: 广西大学 | I33: 土木工程 | L33: 许挣伟
A34: 32 | B34: 项目组 | C34: 黄美为 | D34: 452630199401172821 | E34: 45870 | F34: 45867 | G34: 本科 | H34: 桂林理工大学 | I34: 工程造价 | L34: 黄美为
A35: 33 | B35: 项目组 | C35: 徐美林 | D35: 320922196708153918 | E35: 45992 | F35: 46013 | G35: 本科 | J35: 挂靠 | L35: #N/A
A36: 34 | B36: 项目组 | C36: 李兰 | D36: 370687198712011189 | E36: 45992 | F36: 46013 | G36: 本科 | J36: 挂靠 | L36: #N/A
A37: 35 | B37: 项目组 | C37: 姜鹏举 | D37: 32082619830103561X | E37: 45992 | F37: 46013 | G37: 本科 | J37: 挂靠 | L37: #N/A
L38: #N/A
L39: #N/A
L40: #N/A
L41: #N/A
...

Sheet 项目人员总表
A1: 序号 | B1: 姓名 | C1: 院校 | D1: 专业 | E1: 学历 | F1: 入职时间 | G1: 社保缴纳 | H1: 备注 | I1: 2025年
I2: =SUM(I5:I36) -> 17 | J2: =SUM(J5:J36) -> 17 | K2: =SUM(K5:K36) -> 16 | L2: =SUM(L5:L36) -> 15 | M2: =SUM(M5:M36) -> 15 | N2: =SUM(N5:N36) -> 17 | O2: =SUM(O5:O36) -> 19 | P2: =SUM(P5:P36) -> 20 | ... T2: =SUM(T5:T36) -> 20
I3: 42 | J3: 42 | K3: 41 | L3: 41 | M3: 41 | N3: 44 | O3: 45 | P3: 61 | Q3: 58 | R3: 33 | S3: 33 | T3: 36
I4: 1月 | J4: 2月 | K4: 3月 | L4: 4月 | M4: 5月 | N4: 6月 | O4: 7月 | P4: 8月 | Q4: 9月 | R4: 10月 | S4: 11月 | T4: 12月
A5: 1 | B5: 张鸿志 | C5: 长春电力专科学校 | D5: 高电压技术 | E5: 大专 | F5: 45027 | G5: 45108 | I5: 1 | J5: 1 | K5: 1 | L5: 1 | M5: 1 | N5: 1 | O5: 1 | P5: 1 | Q5: 1 | R5: 1 | S5: 1 | T5: 1
A6: 2 | B6: 孙满涛 | C6: 哈尔滨商业大学 | D6: 土木工程 | E6: 本科 | F6: 45131 | G6: 45139 | I6: 1 | J6: 1 | K6: 1 | L6: 1 | M6: 1 | N6: 1 | O6: 1 | P6: 1 | Q6: 1 | R6: 1 | S6: 1 | T6: 1
A7: 3 | B7: 邹智伟 | C7: 天津大学 | D7: 建筑工程技术 | E7: 大专 | F7: 45174 | G7: 45170 | I7: 1 | J7: 1 | K7: 1 | L7: 1 | M7: 1 | N7: 1 | O7: 1 | P7: 1 | Q7: 1 | R7: 1 | S7: 1 | T7: 1
A8: 4 | B8: 王雷 | C8: 东北农业大学 | D8: 经济管理 | E8: 本科 | F8: 45176 | G8: 45200 | I8: 1 | J8: 1 | K8: 1 | L8: 1 | M8: 1 | N8: 1 | O8: 1 | P8: 1 | Q8: 1 | R8: 1 | S8: 1 | T8: 1
A9: 5 | B9: 张晓青 | C9: 华东政法大学 | D9: 法学 | E9: 本科 | F9: 45233 | G9: 45231 | I9: 1 | J9: 1 | K9: 1 | L9: 1 | M9: 1 | N9: 1 | O9: 1 | P9: 1 | Q9: 1 | R9: 1 | S9: 1 | T9: 1
A10: 6 | B10: 鲍廉梵 | C10: 华东理工大学 | D10: 电子商务 | E10: 大专 | F10: 45376 | G10: 45383 | I10: 1 | J10: 1 | K10: 1 | L10: 1 | M10: 1 | N10: 1 | O10: 1 | P10: 1 | Q10: 1 | R10: 1 | S10: 1 | T10: 1
A11: 7 | B11: 李文强 | C11: 谷城县技工学校 | D11: 电气自动化 | E11: 大专 | F11: 45383 | G11: 45383 | I11: 1 | J11: 1 | K11: 1 | L11: 1 | M11: 1 | N11: 1 | O11: 1 | P11: 1 | Q11: 1 | R11: 1 | S11: 1 | T11: 1
A12: 8 | B12: 薛飞阳 | C12: 广东科技学院 | D12: 应用电子技术 | E12: 大专 | F12: 45383 | G12: 45383 | I12: 1 | J12: 1 | K12: 1 | L12: 1 | M12: 1 | N12: 1 | O12: 1 | P12: 1 | Q12: 1 | R12: 1 | S12: 1 | T12: 1
A13: 9 | B13: 麻凤娟 | C13: 桂林理工大学 | D13: 土木工程 | E13: 本科 | F13: 45363 | G13: 45413 | I13: 1 | J13: 1 | K13: 1 | L13: 1 | M13: 1 | N13: 1 | O13: 1 | P13: 1 | Q13: 1 | R13: 1 | S13: 1 | T13: 1
A14: 10 | B14: 黄丽娇 | C14: 广西水利电力职业技术学院 | D14: 电气自动化技术 | E14: 大专 | F14: 45418 | G14: 45413 | I14: 1 | J14: 1 | K14: 1 | L14: 1 | M14: 1 | N14: 1 | O14: 1 | P14: 1 | Q14: 1 | R14: 1 | S14: 1 | T14: 1
A15: 11 | B15: 韦继勇 | C15: 百色学院 | D15: 工程管理 | E15: 本科 | F15: 45439 | G15: 45444 | I15: 1 | J15: 1 | K15: 1 | L15: 1 | M15: 1 | N15: 1 | O15: 1 | P15: 1 | Q15: 1 | R15: 1 | S15: 1 | T15: 1
A16: 12 | B16: 徐熙堂 | C16: 广西交通职业技术学院 | D16: 汽车电子技术 | E16: 大专 | F16: 45505 | G16: 45505 | I16: 1 | J16: 1 | K16: 1 | L16: 1 | M16: 1 | N16: 1 | O16: 1 | P16: 1 | Q16: 1 | R16: 1 | S16: 1 | T16: 1
... A18: 14 | B18: 韦诚 | C18: 南宁理工学院 | D18: 土木工程 | E18: 本科 | F18: 45575 | G18: 45597 | I18: 1 | J18: 1 | K18: 1 | L18: 1 | M18: 1 | N18: 1 | O18: 1 | P18: 1 | Q18: 1 | R18: 1 | S18: 1 | T18: 1
A19: 15 | B19: 廖梅佟 | C19: 广西水利电力职业技术学院 | D19: 供用电技术 | E19: 大专 | F19: 45644 | I19: 1 | J19: 1 | K19: 1 | L19: 1 | M19: 1 | N19: 1 | O19: 1 | P19: 1 | Q19: 1 | R19: 1 | S19: 1 | T19: 1
A20: 16 | B20: 许方耀 | C20: 广西工程职业学院 | D20: 建筑工程技术 | E20: 大专 | F20: 45809 | G20: 45809 | N20: 1 | O20: 1 | P20: 1 | Q20: 1 | R20: 1 | S20: 1 | T20: 1
A21: 17 | B21: 龙玉涛 | C21: 广西安全工程职业技术学院 | D21: 机电一体化技术专业 | E21: 大专 | F21: 45811 | G21: 45809 | N21: 1 | O21: 1 | P21: 1 | Q21: 1 | R21: 1 | S21: 1 | T21: 1
A22: 18 | B22: 伍世昀 | C22: 广西电力职业技术学校 | D22: 火电厂集控运行 | E22: 大专 | F22: 45831 | G22: 45839 | O22: 1 | P22: 1 | Q22: 1 | R22: 1 | S22: 1 | T22: 1
A23: 19 | B23: 许挣伟 | C23: 广西大学 | D23: 土木工程 | E23: 本科 | F23: 45839 | G23: 45839 | O23: 1 | P23: 1 | Q23: 1 | R23: 1 | S23: 1 | T23: 1
A24: 20 | B24: 黄美为 | C24: 桂林理工大学 | D24: 工程造价 | E24: 本科 | F24: 45867 | G24: 45870 | P24: 1 | Q24: 1 | R24: 1 | S24: 1 | T24: 1
A25: 1 | B25: 宋爱民 | C25: 中国地质大学 | D25: 电气自动化 | E25: 大专 | F25: 44881 | G25: 44866
A26: 2 | B26: 庄保松 | C26: 江苏海洋大学（原淮海工学院） | D26: 土木工程 | E26: 本科 | F26: 44935 | G26: 44927
A27: 3 | B27: 张尉云 | C27: 内蒙古工业大学 | D27: 工程管理 | E27: 本科 | F27: 44999 | G27: 45017
A28: 4 | B28: 黄开国 | C28: 江苏大学 | D28: 机电工程 | E28: 大专 | F28: 45153 | G28: 45139
A29: 5 | B29: 徐旭军 | C29: 湖州师范学院 | D29: 土木工程施工与管理 | E29: 大专 | F29: 45078 | G29: 45078
A30: 6 | B30: 刘银华 | C30: 安徽工业大学 | D30: 建筑工程管理 | E30: 大专 | F30: 44896 | G30: 44896
A31: 7 | B31: 黄建 | C31: 亳州职业技术学院 | D31: 机电一体化技术 | E31: 大专 | F31: 45383 | G31: 45383 | H31: 社保挂靠
A32: 8 | B32: 蒋杰 | C32: 江苏联合职业技术学院 | D32: 机电一体化技术 | E32: 大专 | F32: 45383 | G32: 45383 | H32: 社保挂靠
A33: 9 | B33: 赵宏 | C33: 西南交通大学 | D33: 机电一体化技术 | E33: 大专 | F33: 45383 | G33: 45383 | H33: 社保挂靠
A34: 10 | B34: 黄勇谈 | C34: 广西开放大学 | D34: 工程管理 | E34: 本科 | F34: 45492 | G34: 45505
A35: 11 | B35: 张争争 | C35: 武警黑龙江指挥学院 | D35: 法律 | E35: 大专 | F35: 45108 | G35: 45108 | I35: 1 | J35: 1
A36: 12 | B36: 史文龙 | C36: 哈尔滨理工大学 | D36: 热动 | E36: 本科 | F36: 45027 | G36: 45108 | I36: 1 | J36: 1 | K36: 1
A37: 13 | B37: 缪金鑫 | C37: 江苏城市职业学院 | D37: 机电一体化技术 | E37: 大专 | F37: 45383 | G37: 45383 | H37: 社保挂靠 | I37: 1 | J37: 1 | K37: 1 | L37: 1
A38: 14 | B38: 王国鹏 | C38: 中国石油大学(北 京) | D38: 土木工程 | E38: 本科 | F38: 45513 | G38: 45536 | I38: 1 | J38: 1 | K38: 1 | L38: 1
A39: 15 | B39: 纪飞 | C39: 江苏城市职业学院 | D39: 机电一体化技术 | E39: 大专 | F39: 45778 | M39: 1
A40: 16 | B40: 劳成用 | C40: 桂林电子科技大学 | D40: 建筑环境与能源应用工 | E40: 本科 | F40: 45395 | G40: 45383 | I40: 1 | J40: 1 | K40: 1 | L40: 1 | M40: 1 | N40: 1 | O40: 1
A41: 17 | B41: 郭正洲 | C41: 东北大学 | D41: 机电一体化技术 | E41: 大专 | F41: 45383 | G41: 45383 | H41: 社保挂靠 | I41: 1 | J41: 1 | K41: 1 | L41: 1 | M41: 1 | N41: 1 | O41: 1 | P41: 1 | Q41: 1
...

Sheet RD02建筑工地扬尘防治系统的研发（已结束）
A1: 建筑工地扬尘防治系统的研发
A2: 2023.4.6-2025.3.31
A3: 上海昱奇工程技术发展有限公司
A4: 序号 | B4: 姓名 | C4: 院校 | D4: 专业 | E4: 学历 | F4: 2025年
F5: 1月 | G5: 2月 | H5: 3月 | I5: 已结束
A6: 1 | B6: 张争争 | C6: 武警黑龙江指挥学院 | D6: 法律 | E6: 大专 | F6: √ | G6: √
A7: 2 | B7: 王雷 | C7: 东北农业大学 | D7: 经济管理 | E7: 本科 | F7: √ | G7: √ | H7: √
A8: 3 | B8: 徐旭军 | C8: 湖州师范学院 | D8: 土木工程施工与管理 | E8: 大专
A9: 4 | B9: 孙满涛 | C9: 哈尔滨商业大学 | D9: 土木工程 | E9: 本科 | F9: √ | G9: √ | H9: √
A10: 5 | B10: 劳成用 | C10: 桂林电子科技大学 | D10: 建筑环境与能源应用工 | E10: 本科 | F10: √ | G10: √ | H10: √
A11: 6 | B11: 廖月冬 | C11: 广西科技大学 | D11: 建筑工程专业 | E11: 本科 | F11: √ | G11: √ | H11: √
A12: 7 | B12: 王国鹏 | C12: 中国石油大学(北 京) | D12: 土木工程 | E12: 本科 | F12: √ | G12: √ | H12: √
A13: 8 | B13: 韦诚 | C13: 南宁理工学院 | D13: 土木工程 | E13: 本科 | F13: √ | G13: √ | H13: √
A14: 1 | B14: 史文龙 | C14: 哈尔滨理工大学 | D14: 热动 | E14: 本科 | F14: √ | G14: √ | H14: √
C16: 为本月新增研发人员
C17: 为已离职人员

Sheet RD04建筑施工全流程管控平台的开发
A1: 建筑施工全流程管控平台的开发
A2: 2024.1.5-2025.12.31
A3: 上海昱奇工程技术发展有限公司
A4: 序号 | B4: 姓名 | C4: 院校 | D4: 专业 | E4: 学历 | F4: 2025年
F5: 1月 | G5: 2月 | H5: 3月 | I5: 4月 | J5: 5月 | K5: 6月 | L5: 7月 | M5: 8月 | N5: 9月 | O5: 10月 | P5: 11月 | Q5: 12月
A6: 1 | B6: 鲍廉梵 | C6: {=VLOOKUP(B6:B12,[1]项目人员总表!B5:G38,4,0)} -> 华东理工大学 | D6: =VLOOKUP(B:B,[1]项目人员总表!B:G,5,0) -> 电子商务 | E6: =VLOOKUP(B:B,[1]项目人员总表!B:G,6,0) -> 大专 | F6: √ | G6: √ | H6: √ | I6: √ | J6: √ | K6: √ | L6: √ | M6: √ | N6: √ | O6: √ | P6: √ | Q6: √
A7: 2 | B7: 张晓青 | C7: 华东政法大学 | D7: =VLOOKUP(B:B,[1]项目人员总表!B:G,5,0) -> 法学 | E7: =VLOOKUP(B:B,[1]项目人员总表!B:G,6,0) -> 本科 | F7: √ | G7: √ | H7: √ | I7: √ | J7: √ | K7: √ | L7: √ | M7: √ | N7: √ | O7: √ | P7: √ | Q7: √
A8: 3 | B8: 邹智伟 | C8: 天津大学 | D8: =VLOOKUP(B:B,[1]项目人员总表!B:G,5,0) -> 建筑工程技术 | E8: =VLOOKUP(B:B,[1]项目人员总表!B:G,6,0) -> 大专 | F8: √ | G8: √ | H8: √ | I8: √ | J8: √ | K8: √ | L8: √ | M8: √ | N8: √ | O8: √ | P8: √ | Q8: √
A9: 4 | B9: 麻凤娟 | C9: 桂林理工大学 | D9: =VLOOKUP(B:B,[1]项目人员总表!B:G,5,0) -> 土木工程 | E9: =VLOOKUP(B:B,[1]项目人员总表!B:G,6,0) -> 本科 | F9: √ | G9: √ | H9: √ | I9: √ | J9: √ | K9: √ | L9: √ | M9: √ | N9: √ | O9: √ | P9: √ | Q9: √
A10: 5 | B10: 韦继勇 | C10: 百色学院 | D10: =VLOOKUP(B:B,[1]项目人员总表!B:G,5,0) -> 工程管理 | E10: =VLOOKUP(B:B,[1]项目人员总表!B:G,6,0) -> 本科 | F10: √ | G10: √ | H10: √ | I10: √ | J10: √ | K10: √ | L10: √ | M10: √ | N10: √ | O10: √ | P10: √ | Q10: √
A11: 6 | B11: 陶书华 | C11: 重庆大学 | D11: =VLOOKUP(B:B,[1]项目人员总表!B:G,5,0) -> 土木工程 | E11: =VLOOKUP(B:B,[1]项目人员总表!B:G,6,0) -> 本科 | F11: √ | G11: √ | H11: √ | I11: √ | J11: √ | K11: √ | L11: √ | M11: √ | N11: √ | O11: √ | P11: √ | Q11: √
A12: 7 | B12: 郑学成 | C12: 广西建设职业技术学院 | D12: =VLOOKUP(B:B,[1]项目人员总表!B:G,5,0) -> 建筑工程 | E12: =VLOOKUP(B:B,[1]项目人员总表!B:G,6,0) -> 大专 | F12: √ | G12: √ | H12: √ | I12: √ | J12: √ | K12: √ | L12: √ | M12: √ | N12: √ | O12: √ | P12: √ | Q12: √
A13: 8 | B13: 韦诚 | C13: 南宁理工学院 | D13: 土木工程 | E13: 本科 | I13: √ | J13: √ | K13: √ | L13: √ | M13: √ | N13: √ | O13: √ | P13: √ | Q13: √
A14: 9 | B14: 孙满涛 | C14: 哈尔滨商业大学 | D14: 土木工程 | E14: 本科 | I14: √ | J14: √ | K14: √ | L14: √ | M14: √ | N14: √ | O14: √ | P14: √ | Q14: √
A15: 1 | B15: 王国鹏 | C15: 中国石油大学(北 京) | D15: 土木工程 | E15: 本科 | I15: √
A16: 9 | B16: 廖月冬 | C16: 广西科技大学 | D16: 建筑工程专业 | E16: 本科 | I16: √ | J16: √ | K16: √ | L16: √ | M16: √ | N16: √
A17: 2
A18: 3
A19: 4
A20: 5
A21: 6
A22: 7
C24: 为本月新增研发人员
C25: 为已离职人员

Sheet RD07电力施工管理平台的开发
A1: 电力施工管理平台的开发
A2: 2024.3.5-2026.2.28
A3: 上海昱奇工程技术发展有限公司
A4: 序号 | B4: 姓名 | C4: 院校 | D4: 专业 | E4: 学历 | F4: 2025年
F5: 1月 | G5: 2月 | H5: 3月 | I5: 4月 | J5: 5月 | K5: 6月 | L5: 7月 | M5: 8月 | N5: 9月 | O5: 10月 | P5: 11月 | Q5: 12月
A6: 1 | B6: 徐熙堂 | C6: 广西交通职业技术学院 | D6: 汽车电子技术 | E6: 大专 | F6: √ | G6: √ | H6: √ | I6: √ | J6: √ | K6: √ | L6: √ | M6: √ | N6: √ | O6: √ | P6: √ | Q6: √
A7: 2 | B7: 张鸿志 | C7: 长春电力专科学校 | D7: 高电压技术 | E7: 大专 | F7: √ | G7: √ | H7: √ | I7: √ | J7: √ | K7: √ | L7: √ | M7: √ | N7: √ | O7: √ | P7: √ | Q7: √
A8: 3 | B8: 李文强 | C8: 谷城县技工学校 | D8: 电气自动化 | E8: 大专 | F8: √ | G8: √ | H8: √ | I8: √ | J8: √ | K8: √ | L8: √ | M8: √ | N8: √ | O8: √ | P8: √ | Q8: √
A9: 4 | B9: 薛飞阳 | C9: 广东科技学院 | D9: 应用电子技术 | E9: 大专 | F9: √ | G9: √ | H9: √ | I9: √ | J9: √ | K9: √ | L9: √ | M9: √ | N9: √ | O9: √ | P9: √ | Q9: √
A10: 7 | B10: 黄丽娇 | C10: 广西水利电力职业技术学院 | D10: 电气自动化技术 | E10: 大专 | F10: √ | G10: √ | H10: √ | I10: √ | J10: √ | K10: √ | L10: √ | M10: √ | N10: √ | O10: √ | P10: √ | Q10: √
A11: 9 | B11: 王雷 | C11: 东北农业大学 | D11: 经济管理 | E11: 本科 | I11: √ | J11: √ | K11: √ | L11: √ | M11: √ | N11: √ | O11: √ | P11: √ | Q11: √
A12: 10 | B12: 许方耀 | C12: 广西工程职业学院 | D12: 建筑工程技术 | E12: 大专 | K12: √ | L12: √ | M12: √ | N12: √ | O12: √ | P12: √ | Q12: √
A13: 11 | B13: 龙玉涛 | C13: 广西安全工程职业技术学院 | D13: 机电一体化技术专业 | E13: 大专 | K13: √ | L13: √ | M13: √ | N13: √ | O13: √ | P13: √ | Q13: √
A14: 12 | B14: 伍世昀 | C14: 广西电力职业技术学校 | D14: 火电厂集控运行 | E14: 大专 | L14: √ | M14: √ | N14: √ | O14: √ | P14: √ | Q14: √
A15: 13 | B15: 许挣伟 | C15: 广西大学 | D15: 土木工程 | E15: 本科 | L15: √ | M15: √ | N15: √ | O15: √ | P15: √ | Q15: √
A16: 15 | B16: 黄美为 | C16: 桂林理工大学 | D16: 工程造价 | E16: 本科 | M16: √ | N16: √ | O16: √ | P16: √ | Q16: √
A17: 1 | B17: 蒋杰 | C17: =VLOOKUP(B:B,[1]项目人员总表!B:G,4,0) -> 江苏联合职业技术学院 | D17: =VLOOKUP(B:B,[1]项目人员总表!B:G,5,0) -> 机电一体化技术 | E17: =VLOOKUP(B:B,[1]项目人员总表!B:GF,6,0) -> 大专
A18: 2 | B18: 黄勇谈 | C18: =VLOOKUP(B:B,[1]项目人员总表!B:G,4,0) -> 广西开放大学 | D18: =VLOOKUP(B:B,[1]项目人员总表!B:G,5,0) -> 工程管理 | E18: =VLOOKUP(B:B,[1]项目人员总表!B:GF,6,0) -> 本科
A19: 3 | B19: 缪金鑫 | C19: =VLOOKUP(B:B,[1]项目人员总表!B:G,4,0) -> 江苏城市职业学院 | D19: =VLOOKUP(B:B,[1]项目人员总表!B:G,5,0) -> 机电一体化技术 | E19: =VLOOKUP(B:B,[1]项目人员总表!B:GF,6,0) -> 大专 | F19: √ | G19: √ | H19: √ | I19: √
A20: 4 | B20: 纪飞 | C20: 江苏城市职业学院 | D20: 机电一体化技术 | E20: 大专 | J20: √
A21: 5 | B21: 劳成用 | C21: 桂林电子科技大学 | D21: 建筑环境与能源应用工 | E21: 本科 | I21: √ | J21: √ | K21: √ | L21: √
A22: 6 | B22: 郭正洲 | C22: 东北大学 | D22: 机电一体化技术 | E22: 大专 | F22: √ | G22: √ | H22: √ | I22: √ | J22: √ | K22: √ | L22: √ | M22: √ | N22: √
A23: 7 | B23: 贺斌 | C23: 武汉工程职业技术学院 | D23: 机电一体化技术 | E23: 大专 | F23: √ | G23: √ | H23: √ | I23: √ | J23: √ | K23: √ | L23: √ | M23: √ | N23: √
A24: 8 | B24: 廖梅佟 | C24: 广西水利电力职业技术学院 | D24: 供用电技术 | E24: 大专 | F24: √ | G24: √ | H24: √ | I24: √ | J24: √ | K24: √ | L24: √ | M24: √ | N24: √
A25: 9 | B25: 韦双磊 | C25: 仙桃职业学院 | D25: 机电一体化技术 | E25: 大专 | L25: √ | M25: √ | N25: √
A26: 10
A27: 11
A28: 12
A29: 13
C31: 为本月新增研发人员
C32: 为已离职人员
